Workbook

Sheet Candidature
A1: Date | B1: Type | C1: Nom d'entreprise | D1: Offre | E1: Retour | F1: Information | P1: Date | Q1: Nom hopital | R1: Style | S1: Status
A2: 45985 | B2: Télécom | C2: MyTelec om Entreprises | D2: Sp + Email | E2: En attente | F2: Reçu une adresse mail | P2: 45985 | Q2: LaporteVerte | R2: Spontannée | S2: En attente
A3: 45985 | B3: Télécom | C3: VousFaciliterIT | D3: Spontanée | E3: En attente | P3: 45985 | Q3: Groupe Hospitalier Nord Essonne | R3: Spontannée | S3: En attente
A4: 45985 | B4: Télécom | C4: RTEAM | D4: Spontanée | E4: Refus | F4: Ne prend pas d'alternant | P4: 45985 | Q4: H Paris Est | R4: Spontannée | S4: En attente
A5: 45985 | B5: Télécom | C5: Alleo | D5: Sp + @ + Appel | E5: En attente | F5: Reçu une adresse mail | P5: 45985 | Q5: CH Rives de Seine | R5: Spontannée | S5: En attente
A6: 45985 | B6: Télécom | C6: KTNS | D6: Email | E6: En attente | P6: 45985 | Q6: American Hospital Paris | R6: Spontannée | S6: En attente
A7: 45985 | B7: Télécom | C7: TDF | D7: Sp + Email | E7: En attente | P7: 45985 | Q7: CHSF | R7: Spontannée | S7: En attente
A8: 45985 | B8: Télécom | C8: Paritel | D8: Spontanée | E8: En attente | R8: Spontannée
A9: 45985 | B9: Télécom | C9: Tibco | D9: Spontanée | E9: Refus | F9: Plus d'offre d'alternance
A10: 45985 | B10: Télécom | C10: Rhôn TELECOM | D10: Spontanée | E10: En attente
A11: 45985 | B11: Télécom | C11: KSTelecom | D11: Spontanée | E11: En attente
A12: 45985 | B12: Télécom | C12: MonacoTelecom | D12: Email | E12: Appel reçu | F12: Entretien télé avec une RH
A13: 45985 | B13: Télécom | C13: Com Network | D13: A appeler | E13: En attente
A14: 45985 | B14: Télécom | C14: Telec FR | D14: Spontanée | E14: En attente
A15: 45985 | B15: Télécom | C15: FreePRO | D15: Email | E15: En attente
A16: 45985 | B16: Télécom | C16: Open Global | D16: A appeler | E16: En attente
A17: 45985 | B17: Télécom | C17: ExtremIT | D17: Spontanée | E17: En attente
A18: 45985 | B18: Télécom | C18: ODYC C | D18: A appeler | E18: En attente
A19: 45985 | B19: Télécom | C19: Socotec Construction | D19: A appeler | E19: En attente
A20: 45985 | B20: Télécom | C20: RTE France | D20: Spontanée | E20: En attente
A21: 45986 | B21: Télécom | C21: Fichet Group | D21: H + Email | E21: Refus
A22: 45986 | B22: Télécom | C22: MainCare | D22: LinkdIn | E22: Refus | F22: Mai 2026 pour Septembre
A23: 45986 | B23: Télécom | C23: Evidensee | D23: Sp + Email | E23: En attente
A24: 45986 | B24: Télécom | C24: Groupe Savencia | D24: HelloWork | E24: En attente
A25: 45986 | B25: Télécom | C25: Aix-Marseille Université (AMU) | D25: Email | E25: En attente
A26: 45986 | B26: Télécom | C26: Klapierre | D26: A appeler | E26: En attente | F26: offre
A27: 45986 | B27: Télécom | C27: CDC Informatique | D27: LinkdIn | E27: En attente
A28: 45986 | B28: Télécom | C28: Forsee Power | D28: LinkdIn | E28: Refus | F28: Correspond pas au profil
A29: 45986 | B29: Télécom | C29: JULBO | D29: LinkdIn | E29: En attente
A30: 45986 | B30: Télécom | C30: Extia | D30: Spontanée | E30: Refus
A31: 45986 | B31: Télécom | C31: Leonix | D31: A appeler | E31: En attente
A32: 45987 | B32: Télécom | C32: Sii Group | D32: Sp + Email | E32: En attente | F32: Reçu une adresse mail
A33: 45987 | B33: Télécom | C33: DSTNY | D33: Email | E33: En attente
A34: 45987 | B34: Télécom | C34: Ciel tecom | E34: En attente
A35: 45987 | B35: Télécom | C35: Blue ( Breragne ) | D35: Spontanée | E35: En attente
A36: 45987 | B36: Télécom | C36: Coriolis Entreprise | D36: A appeler | E36: En attente | I36: Colonne1 | J36: Colonne2 | K36: Colonne3 | L36: Colonne4
A37: 45987 | B37: Télécom | C37: keyyo | D37: Spontanée | E37: En attente | I37: Appel reçu | J37: =COUNTIF(E1:E406, "*Appel reçu*") -> 1 | K37: ESN | L37: =COUNTIF(B1:B406, "*ESN*") -> 45
A38: 45987 | B38: Télécom | C38: Open France | D38: Spontanée | E38: En attente | I38: En attente | J38: =COUNTIF(E1:E406, "*En attente*") -> 152 | K38: Télécom | L38: =COUNTIF(B1:B406, "*Télécom*") -> 54
A39: 45987 | B39: ESN | C39: Stelogy | D39: Spontanée | E39: En attente | I39: Refus | J39: =COUNTIF(E1:E406, "*Refus*") -> 30 | K39: FAI | L39: =COUNTIF(B1:B406, "*FAI*") -> 50
A40: 45987 | B40: ESN | C40: CELAD | D40: Spontanée | E40: En attente | I40: Total | J40: =J39+J38+J37 -> 183 | K40: Mairie | L40: =COUNTIF(B1:B406, "*Mairie*") -> 14
...

Sheet Contact
A1: Nom d'entreprise | B1: Adresse mail | C1: Numéro de téléphone | D1: Offre | E1: Colonne1 | J1: =Candidature!Q1 -> Nom hopital | K1: Adresse mail | L1: Numéro de téléphone | M1: Lieu
A2: =Candidature!C2 -> MyTelec om Entreprises | B2: contact@mytelecom-entreprises.fr | C2: 04.78.72.02.11 | E2: alexandre.regis@vditelecom.fr | J2: =Candidature!Q2 -> LaporteVerte | L2: 01.39.63.74.00 | M2: Versaille
A3: =Candidature!C3 -> VousFaciliterIT | B3: contact@vflit.fr | C3: 08.26.04.40.44 | D3: Appel payant flemme | J3: =Candidature!Q3 -> Groupe Hospitalier Nord Essonne
A4: =Candidature!C4 -> RTEAM | B4: contact@recruteam.fr | C4: 04 49 23 03 66 | D4: M.Masto : 06.26.27.67.47 | J4: =Candidature!Q4 -> H Paris Est
A5: =Candidature!C5 -> Alleo | B5: contact@alleo.fr | C5: 01.40.52.30.50 | J5: =Candidature!Q5 -> CH Rives de Seine
A6: =Candidature!C6 -> KTNS | B6: candidature@k-tns.com | C6: 09 86 36 67 11 | J6: =Candidature!Q6 -> American Hospital Paris
A7: =Candidature!C7 -> TDF | B7: rssi.rssi@tdf.fr | C7: 01.55.95.10.00 | J7: =Candidature!Q7 -> CHSF
A8: =Candidature!C8 -> Paritel | B8: web@paritel.fr | C8: 01.85.53.59.49
A9: =Candidature!C9 -> Tibco | B9: contact@tibco.fr | C9: 01.39.86.64.83
A10: =Candidature!C10 -> Rhôn TELECOM | B10: recrutement@rhon-telecom.fr | C10: 04.27.44.41.79
A11: =Candidature!C11 -> KSTelecom | B11: dpo@groupeks.com | C11: 08 25 01 40 16
A12: =Candidature!C12 -> MonacoTelecom | B12: recrutement@monaco-telecom.mc | C12: +377 99 66 33 00
A13: =Candidature!C13 -> Com Network | C13: 08 25 74 56 92
A14: =Candidature!C14 -> Telec FR | B14: peyroutet@peyroutet.fr | C14: 05.59.81.30.30
A15: =Candidature!C15 -> FreePRO | B15: recrutement@freepro.com | C15: 01.83.65.99.00
A16: =Candidature!C16 -> Open Global
A17: =Candidature!C17 -> ExtremIT | C17: 03 20 64 66 06
A18: =Candidature!C18 -> ODYC C | C18: 02.23.27.89.24
A19: =Candidature!C19 -> Socotec Construction | C19: 01.39.08.27.83
A20: =Candidature!C20 -> RTE France
A21: =Candidature!C21 -> Fichet Group | B21: recrutement@fichetgroup.com | C21: 01.34.65.65.34
A22: =Candidature!C22 -> MainCare
A23: =Candidature!C23 -> Evidensee | C23: 08 11 39 23 92 | D23: ApprentiTechnicien Support et Réseau
A24: =Candidature!C24 -> Groupe Savencia | C24: 01.34.58.63.00 | D24: Alternant en Système d'Information
A25: =Candidature!C25 -> Aix-Marseille Université (AMU) | B25: job-ref-ghnhfpe5pd@emploi.beetween.com
A26: =Candidature!C26 -> Klapierre | C26: 01.40.67.54.00
A27: =Candidature!C27 -> CDC Informatique
A28: =Candidature!C28 -> Forsee Power | C28: 01.58.91.69.00 | D28: ALTERNANCE - Informatique
A29: =Candidature!C29 -> JULBO | D29: Assistant Technique Informatique
A30: =Candidature!C30 -> Extia
A31: =Candidature!C31 -> Leonix
A32: =Candidature!C32 -> Sii Group | B32: recrutement_SII-IDF@sii.fr | C32: 01.75.60.16.68
A33: =Candidature!C33 -> DSTNY
A34: =Candidature!C34 -> Ciel tecom
A35: =Candidature!C35 -> Blue ( Breragne )
A36: =Candidature!C36 -> Coriolis Entreprise | C36: 01 34 90 06 08
A37: =Candidature!C37 -> keyyo
A38: =Candidature!C38 -> Open France
A39: =Candidature!C39 -> Stelogy
A40: =Candidature!C40 -> CELAD
...

Sheet Feuil3
A1: Statut | B1: Candidature
A2: J'ai postulé | B2: Spontanée
A3: En attente | B3: Email
A4: Refus | B4: Sp + Email
A5: Appel reçu | B5: Sp + HW
A6: Appel émis | B6: HelloWork
B7: H + Email
B8: Sp + Appel
B9: LinkdIn
B10: Sp + @ + Appel
B11: Indeed
B12: A appeler
B13: Appel émis
B14: La Bonne Alternance
