Workbook

Sheet Candidature
A1: Date | B1: Type | C1: Nom d'entreprise | D1: Offre | E1: Retour | F1: Information
A2: 46003 | B2: Télécoms | C2: Orange | D2: Technicien Service Client | E2: En attente
A3: 46003 | B3: Télécoms | C3: Orange | D3: Conseiller Client Back Office | E3: En attente
A4: 46003 | B4: Télécoms | C4: Orange | D4: Chargé(e) de Projet | E4: Refus | F4: Pas adapté
A5: 46003 | C5: Orange
A6: 46003 | C6: Safran | D6: Mise en Place d'Une Solution de Virtualisation | E6: En attente
A7: 46003 | C7: MBDA | D7: Création d'Un Outil de Gestion et de Capitalisation | E7: En attente
A8: 46003 | C8: SUEZ | D8: Développement Informatique | E8: En attente
A9: 46003 | C9: MBDA | D9: Développement d'Un Site Intranet Métier | E9: En attente
A10: 46003 | C10: Socotec | D10: Ingénieur Informatique Embarqué | E10: En attente
A11: 46003 | C11: Dassault Systèmes | D11: Charge de Projets Systemes Informatiques | E11: En attente
A12: 46003 | C12: EDF | D12: Ingénieure ou Ingénieur Informatique | E12: En attente
A13: 46003 | C13: Ariane Group | D13: Technicienne - Technicien Informatique | E13: En attente
A14: 46003 | C14: RTE | D14: Chef de Projets Informatique | E14: Refus | F14: Ne correspond pas aux prérequis
A15: 46003 | C15: Groupe SII | D15: Ingénieur·e Réseau Informatique | E15: En attente
A16: 46003 | C16: Evidensee | D16: Technicien·ne Support et Réseau | E16: En attente
A17: 46003 | C17: OTC FLOW FRANCE | D17: Administrateur Réseaux et Systèmes | E17: En attente
A18: 46003 | C18: Spie | D18: technicien Supérieur Systèmes et Réseaux | E18: En attente
A19: 46003 | C19: Bureau Veritas | D19: Chef de projet Telecom | E19: En attente
A20: 46003 | C20: Groupe SETEC | D20: Ingénieur systèmes d'informations et réseaux | E20: En attente
A21: 46003 | C21: ROUX Informatique | D21: Technicien Informatique Systèmes & Réseaux | E21: En attente
D22: Stage soutien informatique
I36: Colonne1 | J36: Colonne2 | K36: Colonne3 | L36: Colonne4
I37: Appel reçu | J37: =COUNTIF(E1:E410, "*Appel reçu*") -> 0 | K37: ESN | L37: =COUNTIF(B1:B410, "*ESN*") -> 0
I38: En attente | J38: =COUNTIF(E1:E410, "*En attente*") -> 17 | K38: Télécom | L38: =COUNTIF(B1:B410, "*Télécom*") -> 3
I39: Refus | J39: =COUNTIF(E1:E410, "*Refus*") -> 2 | K39: FAI | L39: =COUNTIF(B1:B410, "*FAI*") -> 0
I40: Total | J40: =J39+J38+J37 -> 19 | K40: Mairie | L40: =COUNTIF(B1:B410, "*Mairie*") -> 0

Sheet Crouz
A1: Date | B1: Nom hopital | C1: Style | D1: Voiture | E1: Train | F1: Euro | G1: Type | L1: Colonne1 | M1: Colonne2 | N1: Colonne3 | O1: Colonne4 | P1: Colonne5
L2: La Sirène de Paris | M2: Agent d'accueil Week End | N2: CDI | O2: Paris 14 ème | P2: 9.81
B3: Logement individuel - Evry- Aunettes | C3: Evry | D3: 1h15 | E3: 1h27 | F3: 260 euro
B4: Résidence Louise Bourgeois | C4: Antony | D4: 26 min | E4: 43 min | F4: 500 euro
B5: Résidence Les écuries Malaquais | C5: Saint-Cloud | D5: 35 min | E5: 59 min | G5: Logement individuel
B6: Résidence Simone Weil | C6: Boulogne Billancourt | D6: 30 min | F6: 400 euro | G6: Logement individuel
B7: Orsay-L Ile | C7: Bures sur Yvette | D7: 45 min | E7: 37 min | F7: 401 euro | G7: Logement individuel
B8: Ulis | C8: Les ULIS | D8: 28-1h | E8: 51 min | F8: 180 euro | G8: Collocation
B13: Chambre | C13: Meudon | D13: 30 min | E13: 1h08 | F13: 470 | G13: chez un propriétaire
B14: Chambre | C14: L'Haÿ-les-Roses | D14: 4 min | E14: 10 min | F14: 590 | G14: en colocation
B15: Chambre | C15: Villejuif | D15: 10 min | E15: 30 min | F15: 600 | G15: chez un propriétaire
B16: Studio T1 | C16: Paris 18 ème | D16: 55 min | E16: 1h | F16: 471 | G16: indépendant
B17: Chambre | C17: Issy les Moulineaux | D17: 26 min | E17: 1h | F17: 600 | G17: chez un propriétaire

Sheet Contact
A1: Nom d'entreprise | B1: Numéro de téléphone | C1: Adresse mail | D1: Offre | E1: Colonne1 | J1: =Candidature!Q1 -> 0 | K1: Adresse mail | L1: Numéro de téléphone | M1: Lieu
A2: =Candidature!C2 -> Orange | E2: alexandre.regis@vditelecom.fr | J2: =Candidature!Q2 -> 0 | L2: 01.39.63.74.00 | M2: Versaille
A3: =Candidature!C3 -> Orange | J3: =Candidature!Q3 -> 0
A4: =Candidature!C4 -> Orange | J4: =Candidature!Q4 -> 0
A5: =Candidature!C5 -> Orange | J5: =Candidature!Q5 -> 0
A6: =Candidature!C6 -> Safran | B6: 01 40 60 80 80 | C6: =HYPERLINK("[https://www.google.com/search?q=](https://www.google.com/search?q=)"&A1&"+ numéro + de + téléphone","Rechercher"&A1) -> RechercherNom d'entreprise | J6: =Candidature!Q6 -> 0
A7: =Candidature!C7 -> MBDA | B7: 01 71 54 10 00 | C7: =HYPERLINK("[https://www.google.com/search?q=](https://www.google.com/search?q=)"&A2&"+ numéro + de + téléphone","Rechercher"&A2) -> RechercherOrange | J7: =Candidature!Q7 -> 0
A8: =Candidature!C8 -> SUEZ | B8: 01 58 81 20 00 | C8: =HYPERLINK("[https://www.google.com/search?q=](https://www.google.com/search?q=)"&A3&"+ numéro + de + téléphone","Rechercher"&A3) -> RechercherOrange
A9: =Candidature!C9 -> MBDA | B9: 01 40 60 80 80 | C9: =HYPERLINK("[https://www.google.com/search?q=](https://www.google.com/search?q=)"&A4&"+ numéro + de + téléphone","Rechercher"&A4) -> RechercherOrange
A10: =Candidature!C10 -> Socotec | B10: 01 30 12 80 00 | C10: =HYPERLINK("[https://www.google.com/search?q=](https://www.google.com/search?q=)"&A5&"+ numéro + de + téléphone","Rechercher"&A5) -> RechercherOrange
A11: =Candidature!C11 -> Dassault Systèmes | B11: 01 61 62 61 62 | C11: =HYPERLINK("[https://www.google.com/search?q=](https://www.google.com/search?q=)"&A6&"+ numéro + de + téléphone","Rechercher"&A6) -> RechercherSafran
A12: =Candidature!C12 -> EDF | B12: 01 40 42 22 22 | C12: =HYPERLINK("[https://www.google.com/search?q=](https://www.google.com/search?q=)"&A7&"+ numéro + de + téléphone","Rechercher"&A7) -> RechercherMBDA
A13: =Candidature!C13 -> Ariane Group | B13: 01 39 06 12 34 | C13: =HYPERLINK("[https://www.google.com/search?q=](https://www.google.com/search?q=)"&A8&"+ numéro + de + téléphone","Rechercher"&A8) -> RechercherSUEZ
A14: =Candidature!C14 -> RTE | B14: 01 41 02 23 45 | C14: =HYPERLINK("[https://www.google.com/search?q=](https://www.google.com/search?q=)"&A9&"+ numéro + de + téléphone","Rechercher"&A9) -> RechercherMBDA
A15: =Candidature!C15 -> Groupe SII | B15: 01 53 92 37 00 | C15: =HYPERLINK("[https://www.google.com/search?q=](https://www.google.com/search?q=)"&A10&"+ numéro + de + téléphone","Rechercher"&A10) -> RechercherSocotec
A16: =Candidature!C16 -> Evidensee | B16: 08 11 39 23 92 | C16: =HYPERLINK("[https://www.google.com/search?q=](https://www.google.com/search?q=)"&A11&"+ numéro + de + téléphone","Rechercher"&A11) -> RechercherDassault Systèmes
A17: =Candidature!C17 -> OTC FLOW FRANCE | B17: 01 88 24 25 17 | C17: =HYPERLINK("[https://www.google.com/search?q=](https://www.google.com/search?q=)"&A12&"+ numéro + de + téléphone","Rechercher"&A12) -> RechercherEDF
A18: =Candidature!C18 -> Spie | B18: 01 34 41 81 81 | C18: =HYPERLINK("[https://www.google.com/search?q=](https://www.google.com/search?q=)"&A13&"+ numéro + de + téléphone","Rechercher"&A13) -> RechercherAriane Group
A19: =Candidature!C19 -> Bureau Veritas | B19: 09 69 39 10 09 | C19: =HYPERLINK("[https://www.google.com/search?q=](https://www.google.com/search?q=)"&A14&"+ numéro + de + téléphone","Rechercher"&A14) -> RechercherRTE
... A21: =Candidature!C21 -> ROUX Informatique | B21: 01 88 40 53 06 | C21: =HYPERLINK("[https://www.google.com/search?q=](https://www.google.com/search?q=)"&A16&"+ numéro + de + téléphone","Rechercher"&A16) -> RechercherEvidensee
A22: =Candidature!C26 -> 0 | B22: 01 88 40 53 06 | C22: =HYPERLINK("[https://www.google.com/search?q=](https://www.google.com/search?q=)"&A17&"+ numéro + de + téléphone","Rechercher"&A17) -> RechercherOTC FLOW FRANCE
A23: =Candidature!C27 -> 0 | C23: =HYPERLINK("[https://www.google.com/search?q=](https://www.google.com/search?q=)"&A18&"+ numéro + de + téléphone","Rechercher"&A18) -> RechercherSpie
A24: =Candidature!C28 -> 0 | C24: =HYPERLINK("[https://www.google.com/search?q=](https://www.google.com/search?q=)"&A19&"+ numéro + de + téléphone","Rechercher"&A19) -> RechercherBureau Veritas
A25: =Candidature!C29 -> 0
A26: =Candidature!C30 -> 0
A27: =Candidature!C31 -> 0
A28: =Candidature!C32 -> 0
A29: =Candidature!C33 -> 0 | B29: 01 34 41 81 81
A30: =Candidature!C34 -> 0
A31: =Candidature!C35 -> 0
A32: =Candidature!C36 -> 0
A33: =Candidature!C37 -> 0
A34: =Candidature!C38 -> 0
A35: =Candidature!C39 -> 0
A36: =Candidature!C40 -> 0 | C36: 01 34 90 06 08
A37: =Candidature!C41 -> 0
A38: =Candidature!C42 -> 0
A39: =Candidature!C43 -> 0
A40: =Candidature!C44 -> 0
A41: =Candidature!C45 -> 0
...

Sheet Feuil3
A1: Statut | B1: Candidature
A2: J'ai postulé | B2: Spontanée
A3: En attente | B3: Email
A4: Refus | B4: Sp + Email
A5: Appel reçu | B5: Sp + HW
A6: Appel émis | B6: HelloWork
B7: H + Email
B8: Sp + Appel
B9: LinkdIn
B10: Sp + @ + Appel
B11: Indeed
B12: A appeler
B13: Appel émis
B14: La Bonne Alternance
